// Copyright (c) 2020 WSO2 Inc. (http://www.wso2.org) All Rights Reserved.
//
// WSO2 Inc. licenses this file to you under the Apache License,
// Version 2.0 (the "License"); you may not use this file except
// in compliance with the License.
// You may obtain a copy of the License at
//
// http://www.apache.org/licenses/LICENSE-2.0
//
// Unless required by applicable law or agreed to in writing,
// software distributed under the License is distributed on an
// "AS IS" BASIS, WITHOUT WARRANTIES OR CONDITIONS OF ANY
// KIND, either express or implied.  See the License for the
// specific language governing permissions and limitations
// under the License.
import ballerina/jballerina.java;

function testOnFailEdgeTestcases() {
    testUnreachableCodeWithIf();
    testSimpleOnFailWithoutVariable();
    testMultiLevelOnFail();
    testMultiLevelOnFailWithoutVariableVariationOne();
    testMultiLevelOnFailWithoutVariableVariationTwo();
    testMultiLevelOnFailWithoutVariableVariationThree();
    testRetryOnFailWithinWhile();
    testOnFailWithinAnonFunc();
    testRetryOnFailWithinObjectFunc();
    testFailExprWithinOnFail();
    testCheckExprWithinOnFail();
    testFailPassWithinOnFail();
    testTypeNarrowingInsideOnfail();
    testBreakWithinOnfail();
    assertEquality(" -> Before error thrown,  -> Error caught at level #1 -> Error caught at levet #2",
    testReturnWithinOnfail());
    assertEquality(1, testIntReturnWithinOnfail());
    testBreakWithinOnfailForOuterLoop();
    assertEquality(44, testLambdaFunctionWithOnFail());
    testOnFailWithinInLineServiceObj();
    assertTrue(testOnFailInAnonFunctionExpr() is ());
}

function testUnreachableCodeWithIf(){
    int i = 0;
    string str = "";

    while (i < 3) {
        if(i == 2) {
            str += " -> Before error thrown";
            fail getError();
        }

        str += " -> Inside loop: " + i.toString() + ",";
        i = i + 1;
    } on fail error e {
        str += " -> Error caught!";
    }

    assertEquality(" -> Inside loop: 0, -> Inside loop: 1, -> Before error thrown -> Error caught!", str);
}

function testMultiLevelOnFail() {
    int i = 0;
    string str = "";

    while (i < 2) {
        do {
            str += " -> Before error thrown, ";
            fail getError();
        } on fail error e {
            str += " -> Error caught at level #1";
        }

        i = i + 1;
    } on fail error e {
        str += " -> Error caught at levet #2";
    }

    assertEquality(" -> Before error thrown,  -> Error caught at level #1 -> Before error thrown,  -> Error caught at level #1", str);
}

function testMultiLevelOnFailWithoutVariableVariationOne() {
    int i = 1;
    string str = "";

    while i <= 2 {
        do {
            str += " -> Iteration " + i.toString() + ", ";
            fail getError();
        } on fail {
            str += " -> On Fail #" + i.toString();
        }
        i = i + 1;
    } on fail error e {
        str += " -> On Fail Final";
    }

    assertEquality(" -> Iteration 1,  -> On Fail #1 -> Iteration 2,  -> On Fail #2", str);
}

function testMultiLevelOnFailWithoutVariableVariationTwo() {
    int i = 1;
    string str = "";

    while i <= 2 {
        do {
            str += " -> Iteration " + i.toString() + ", ";
            fail getError();
        } on fail error e {
            str += " -> On Fail #" + i.toString();
        }
        i = i + 1;
    } on fail {
        str += " -> On Fail Final";
    }

    assertEquality(" -> Iteration 1,  -> On Fail #1 -> Iteration 2,  -> On Fail #2", str);
}

function testMultiLevelOnFailWithoutVariableVariationThree() {
    int i = 1;
    string str = "";

    while i <= 2 {
        do {
            str += " -> Iteration " + i.toString() + ", ";
            fail getError();
        } on fail {
            str += " -> On Fail #" + i.toString();
        }
        i = i + 1;
    } on fail {
        str += " -> On Fail Final";
    }

    assertEquality(" -> Iteration 1,  -> On Fail #1 -> Iteration 2,  -> On Fail #2", str);
}

public class MyRetryManager {
    private int count;
    public function init(int count = 3) {
        self.count = count;
    }
    public function shouldRetry(error e) returns boolean {
        if e is error && self.count >  0 {
            self.count -= 1;
            return true;
        } else {
            return false;
        }
    }
}

function testRetryOnFailWithinWhile() {
    int i = 0;
    while (i < 2) {
        string str = "start";
        int count = 0;
        retry<MyRetryManager> (2) {
            count = count+1;
            if (count < 2) {
                str += (" attempt " + count.toString() + ":error,");
                fail trxError();
            }
            str += (" attempt "+ count.toString() + ":result returned end.");
        } on fail error e {
            str += "-> error handled";
        }

        i = i+1;
        assertEquality("start attempt 1:error, attempt 2:result returned end.", str);
    }

    assertEquality(2, i);
}

public function testOnFailWithinAnonFunc() {
    function () anonFunction =
        function () {
            int i = 0;
            string str = "";

            while (i < 2) {
                do {
                    str += " -> Before error thrown, ";
                    fail getError();
                } on fail error e {
                    str += " -> Error caught at level #1";
                }

                i = i + 1;
            } on fail error e {
                str += " -> Error caught at levet #2";
            }

        assertEquality(" -> Before error thrown,  -> Error caught at level #1 -> Before error thrown,  -> Error caught at level #1", str);
    };

    anonFunction();
}

class TestClass {
    function runOnFailClause() returns string {
        int i = 0;
        string str = "";

        while (i < 2) {
            do {
                str += " -> Before error thrown, ";
                fail getError();
            } on fail error e {
                str += " -> Error caught at level #1";
            }

            i = i + 1;
        } on fail error e {
            str += " -> Error caught at levet #2";
        }
        return str;
    }
}

function testRetryOnFailWithinObjectFunc() {
    TestClass testClass = new ();
    string str = testClass.runOnFailClause();
    assertEquality(" -> Before error thrown,  -> Error caught at level #1 -> Before error thrown,  -> Error caught at level #1", str);
}

function testFailExprWithinOnFail() {
    int i = 0;
    string str = "";
    while (i < 2) {
        do {
            str += " -> Before error thrown, ";
            i = i + 1;
            fail getError();
        } on fail error e {
            str += " -> Error caught at level #1";
            fail getError();
        }
    } on fail error e {
        str += " -> Error caught at level #2";
    }

    assertEquality(" -> Before error thrown,  -> Error caught at level #1 -> Error caught at level #2", str);
}

function testCheckExprWithinOnFail() {
    int i = 0;
    string str = "";
    while (i < 2) {
        do {
            str += " -> Before error thrown, ";
            i = i + 1;
            fail getError();
        } on fail error e {
            str += " -> Error caught at level #1";
            int val = check getCheckError();
        }
    } on fail error e {
        str += " -> Error caught at level #2";
    }

    assertEquality(" -> Before error thrown,  -> Error caught at level #1 -> Error caught at level #2", str);
}

function testFailPassWithinOnFail() {
    int i = 0;
    string str = "";
    do {
        do {
            str += "-> Before error thrown";
            i = i + 1;
            int ign = check getCheckError();
            str += " -> After error thrown, ";
        } on fail error e {
            str += " -> Error caught at level #1";
            int ii = check getCheckInt();
            str += " -> After level #1 check";
        }
        str += " -> After level #1 on-fail";
    } on fail error e {
        str += " -> Error caught at level #2";
    }
    str += " -> After handling all failures";

    assertEquality("-> Before error thrown -> Error caught at level #1 -> After level #1 check"
    + " -> After level #1 on-fail -> After handling all failures", str);
}

function testTypeNarrowingInsideOnfail() {
    string str = "";
    do {
        do {
            str += "-> Before error thrown";
            int parsedStr = check getCheckError();
        } on fail error e1 {
            str += " -> Error caught at level #1. Retrying...";
            var res = getCheckError();
            if (res is int) {
                str += " -> Should not reach here";
            } else {
                str += " -> Retry failed";
                fail res;
            }
        }
    } on fail error e {
        str += " -> Error caught at level #2";
    }
    str += " -> After handling all failures";

    assertEquality("-> Before error thrown -> Error caught at level #1. Retrying... -> Retry failed"
        + " -> Error caught at level #2 -> After handling all failures", str);
}

function testBreakWithinOnfail() {
    string str = "";
    do {
        str += "-> Before error thrown";
        fail getError();
    } on fail error e {
        str += " -> Error caught! ";
        int[] arr = [1, 2, 3];
        foreach int digit in arr {
            if (digit > 1) {
                break;
            }
            str += "Loop broke with digit: " + digit.toString();
        }
    }

    assertEquality("-> Before error thrown -> Error caught! Loop broke with digit: 1", str);
}

function testReturnWithinOnfail() returns string {
    int i = 0;
    string str = "";
    while (i < 2) {
        do {
            str += " -> Before error thrown, ";
            fail getError();
        } on fail error e {
            str += " -> Error caught at level #1";
            fail getError();
        }
        i = i + 1;
    } on fail error e {
        str += " -> Error caught at levet #2";
        return str;
    }
    return "should not reach here";
}

function testIntReturnWithinOnfail() returns int {
    int i = 1;
    while (i < 2) {
        do {
            fail getError();
        } on fail error e {
            fail getError();
        }
        i = i + 1;
    } on fail error e {
        return i;
    }
    return 0;
}

function testBreakWithinOnfailForOuterLoop() {
    string str = "";
    foreach int digit in 1 ... 5 {
        do {
            fail getError();
        } on fail error e {
            if (digit < 4) {
                str += "Loop continued with digit: " + digit.toString() + " ->";
                continue;
            } else {
                str += "Loop broke with digit: " + digit.toString();
                break;
            }
        }
    }
    assertEquality("Loop continued with digit: 1 ->Loop continued with digit: 2 ->Loop continued with digit: 3 " +
    "->Loop broke with digit: 4", str);
}

function testLambdaFunctionWithOnFail() returns int {
    var lambdaFunc = function () returns int {
          int a = 10;
          int b = 11;
          int c = 0;
          do {
              error err = error("custom error", message = "error value");
              c = a + b;
              fail err;
          } on fail error e {
              function (int, int) returns int arrow = (x, y) => x + y + a + b + c;
              a = arrow(1, 1);
          }
          return a;
    };
    return lambdaFunc();
}

function testSimpleOnFailWithoutVariable() {
    string str = "";
    do {
        error err = error("Custom error thrown explicitly.");
        fail err;
    } on fail {
        str += "On Fail Executed";
    }
     assertEquality("On Fail Executed", str);
}

function getCheckError()  returns int|error {
    error err = error("Custom Error");
    return err;
}

function getCheckInt()  returns int|error {
    return 0;
}

function trxError()  returns error {
    return error("TransactionError");
}

function getError() returns error {
    error err = error("Custom Error");
    return err;
}

public class Listener {

    public isolated function 'start() returns error? {
        return externStart(self);
    }
    public isolated function gracefulStop() returns error? {
    }
    public isolated function immediateStop() returns error? {
    }
    public isolated function detach(service object {} s) returns error? {
    }
    public isolated function attach(service object {} s, string[]|string? name = ()) returns error? {
        return self.register(s, name);
    }
    isolated function register(service object {} s, string[]|string? name) returns error? {
        return externAttach(s, name);
    }

    public function init() returns error? {
        check externLInit(self);
    }
}

type S service object {
};

service S / on new Listener() {
    resource isolated function get foo() returns service object {} {
        return service object {
            resource function get foo() returns string {
                do {
                    _ = check getCheckError();
                    return "should not reach here";
                } on fail error e {
                    return "Error thrown from on-fail: " + e.message();
                }
            }
        };
    }

    resource isolated function get bar() returns service object {} {
        return service object {
            resource function get bar() returns string {
                do {
                    do {
                        _ = check getCheckError();
                    } on fail error e1 {
                        fail e1;
                    }
                } on fail error e2 {
                    return "Error thrown from on-fail: " + e2.message();
                }
                return "should not reach here";
            }
        };
    }
}

function getService() returns object {} = @java:Method {
    'class: "org/ballerinalang/nativeimpl/jvm/servicetests/ServiceValue",
    name: "getService"
} external;

function reset() = @java:Method {
    'class: "org/ballerinalang/nativeimpl/jvm/servicetests/ServiceValue",
    name: "reset"
} external;

public function callMethod(service object {} s, string name) returns future<any|error> = @java:Method {
    'class: "org/ballerinalang/nativeimpl/jvm/servicetests/ServiceValue",
    name: "callMethod"
} external;

isolated function externLInit(object {} o) returns error? = @java:Method {
    'class: "org/ballerinalang/nativeimpl/jvm/servicetests/ServiceValue",
    name: "listenerInit"
} external;

isolated function externAttach(service object {} s, string[]|string? name) returns error? = @java:Method {
    'class: "org/ballerinalang/nativeimpl/jvm/servicetests/ServiceValue",
    name: "attach"
} external;

isolated function externStart(object {} o) returns error? = @java:Method {
    'class: "org/ballerinalang/nativeimpl/jvm/servicetests/ServiceValue",
    name: "start"
} external;

function testOnFailWithinInLineServiceObj() {
    service object {} serviceObj1 = <service object {}>
            (checkpanic (wait callMethod(<service object {}>getService(), "$get$foo")));
    string str1 = <string>(checkpanic (wait callMethod(serviceObj1, "$get$foo")));
    assertEquality(str1, "Error thrown from on-fail: Custom Error");

    service object {} serviceObj2 = <service object {}>
                (checkpanic (wait callMethod(<service object {}>getService(), "$get$bar")));
    string str2 = <string>(checkpanic (wait callMethod(serviceObj2, "$get$bar")));
    assertEquality(str2, "Error thrown from on-fail: Custom Error");

    reset();
}

function testOnFailInAnonFunctionExpr() returns error? {
    stream<string, error?> strStream = ["a1", "a2"].toStream();
    error? result1 = ();
    check strStream.forEach(function(string str) {
        do {
            int _ = check int:fromString(str);
        } on fail error e {
            //loop continues as the error is handled. result should contain the error for second element
            result1 = e;
        }
    });
    assertTrue(result1 is error);
    assertEquality((<error>result1).detail().get("message"), "'string' value 'a2' cannot be converted to 'int'");

    string[] strArray = ["a1", "a2"];
    error? result2 = ();
    strArray.forEach(function(string str) {
        do {
            do {
                int _ = check int:fromString(str);
            } on fail error e1 {
                fail e1;
            }
        } on fail error e2 {
            result2 = e2;
        }
    });
    assertEquality((<error>result2).detail().get("message"), "'string' value 'a2' cannot be converted to 'int'");
}

//-------------------------------------------------------------------------------

type AssertionError error;

function assertTrue(any|error actual) {
    assertEquality(true, actual);
}

function assertFalse(any|error actual) {
    assertEquality(false, actual);
}

function assertEquality(any|error expected, any|error actual) {
    if expected is anydata && actual is anydata && expected == actual {
        return;
    }

    if expected === actual {
        return;
    }

    string expectedValAsString = expected is error ? expected.toString() : expected.toString();
    string actualValAsString = actual is error ? actual.toString() : actual.toString();
    panic error AssertionError("AssertionError",
                            message = "expected '" + expectedValAsString + "', found '" + actualValAsString + "'");
}
