Compiling source
	intg_tests/rerun_failed:0.0.0

Running Tests with Coverage

	rerun_failed

testFunctionFail1: has failed.


testFunctionFail2: has failed.


		Test execution time :*****ms


		[fail] testFunctionFail1:

		    error {ballerina/test:0}TestError ("Failed!")
				callableName: createBallerinaError moduleName: ballerina.test.0 fileName: assert.bal lineNumber: 41
				callableName: assertTrue moduleName: ballerina.test.0 fileName: assert.bal lineNumber: 61
				callableName: testFunctionFail1 moduleName: intg_tests.rerun_failed$test.0.tests.main_test fileName: tests/main_test.bal lineNumber: 35
				callableName: testFunctionFail1$lambda2$ moduleName: intg_tests.rerun_failed$test.0.tests.test_execute-generated_*****lineNumber: 6
			

		[fail] testFunctionFail2:

		    error {ballerina/test:0}TestError ("Failed!")
				callableName: createBallerinaError moduleName: ballerina.test.0 fileName: assert.bal lineNumber: 41
				callableName: assertTrue moduleName: ballerina.test.0 fileName: assert.bal lineNumber: 61
				callableName: testFunctionFail2 moduleName: intg_tests.rerun_failed$test.0.tests.main_test fileName: tests/main_test.bal lineNumber: 41
				callableName: testFunctionFail2$lambda3$ moduleName: intg_tests.rerun_failed$test.0.tests.test_execute-generated_*****lineNumber: 7
			


		0 passing
		2 failing
		0 skipped

Generating Test Report
	rerun-failed-tests/target/report/test_results.json

error: there are test failures